<?xml version="1.0" ?>
<robot name="ar1" xmlns:xacro="http://www.ros.org/wiki/xacro">

<xacro:include filename="$(find ar1_description)/urdf/materials.xacro" />
<!--xacro:include filename="$(find ar1_description)/urdf/ar1.trans" /-->
<xacro:include filename="$(find ar1_description)/urdf/ar1.gazebo" />

<!-- Dummy lidar link for plugin -->
<link name="lidar_link">
</link>

<!-- Dummy lidar joint -->
<joint name="lidar_dummy_joint" type="fixed">
  <origin xyz="0.0 0.0 .12" rpy="0 0 0" />
  <parent link="lidar_1"/>
  <child link="lidar_link" />
</joint>
<!-- 
<link name="base_footprint">

</link> -->

<link name="base_link">
  <inertial>
    <origin xyz="-0.005559722499310211 8.478267444090186e-17 0.0025" rpy="0 0 0"/>
    <mass value="13.473570549169931"/>
    <inertia ixx="0.247816" iyy="0.725608" izz="0.973368" ixy="0.0" iyz="0.0" ixz="0.0"/>
  </inertial>
  <visual>
    <origin xyz="0 0 0" rpy="0 0 0"/>
    <geometry>
      <mesh filename="package://ar1_description/meshes/base_link.stl" scale="0.001 0.001 0.001"/>
    </geometry>
    <material name="silver"/>
  </visual>
  <collision>
    <origin xyz="0 0 0" rpy="0 0 0"/>
    <geometry>
      <mesh filename="package://ar1_description/meshes/base_link.stl" scale="0.001 0.001 0.001"/>
    </geometry>
  </collision>
</link>

<!-- <joint name="base_joint" type="fixed">
  <origin xyz="0.0 0.0 0.0" rpy="0 0.0 0"/>
  <parent link="base_footprint"/>
  <child link="base_link"/>
  <axis xyz="0.0 0.0 0.0"/> 
</joint> -->

<link name="drive_wheel_bracket_left_1">
  <inertial>
    <origin xyz="-0.012999999999986748 0.020000000000000046 -0.022013913452018436" rpy="0 0 0"/>
    <mass value="0.3924130918816367"/>
    <inertia ixx="8.5e-05" iyy="0.000196" izz="0.000138" ixy="-0.0" iyz="-0.0" ixz="-0.0"/>
  </inertial>
  <visual>
    <origin xyz="-0.013 -0.125 -0.0" rpy="0 0 0"/>
    <geometry>
      <mesh filename="package://ar1_description/meshes/drive_wheel_bracket_left_1.stl" scale="0.001 0.001 0.001"/>
    </geometry>
    <material name="silver"/>
  </visual>
  <collision>
    <origin xyz="-0.013 -0.125 -0.0" rpy="0 0 0"/>
    <geometry>
      <mesh filename="package://ar1_description/meshes/drive_wheel_bracket_left_1.stl" scale="0.001 0.001 0.001"/>
    </geometry>
  </collision>
</link>

<link name="drive_wheel_bracket_right_1">
  <inertial>
    <origin xyz="-0.012999999999986748 -0.020000000000000046 -0.022013913452018367" rpy="0 0 0"/>
    <mass value="0.3924130918816367"/>
    <inertia ixx="8.5e-05" iyy="0.000196" izz="0.000138" ixy="-0.0" iyz="-0.0" ixz="-0.0"/>
  </inertial>
  <visual>
    <origin xyz="-0.013 0.125 -0.0" rpy="0 0 0"/>
    <geometry>
      <mesh filename="package://ar1_description/meshes/drive_wheel_bracket_right_1.stl" scale="0.001 0.001 0.001"/>
    </geometry>
    <material name="silver"/>
  </visual>
  <collision>
    <origin xyz="-0.013 0.125 -0.0" rpy="0 0 0"/>
    <geometry>
      <mesh filename="package://ar1_description/meshes/drive_wheel_bracket_right_1.stl" scale="0.001 0.001 0.001"/>
    </geometry>
  </collision>
</link>

<link name="caster_front_left_1">
  <inertial>
    <origin xyz="0.021081833227837632 -0.04996287933977797 -0.059552380235665725" rpy="0 0 0"/>
    <mass value="0.7818323769298068"/>
    <inertia ixx="0.000725" iyy="0.001027" izz="0.000456" ixy="-0.0" iyz="0.0" ixz="0.000214"/>
  </inertial>
  <visual>
    <origin xyz="-0.287845 -0.205 -0.0" rpy="0 0 0"/>
    <geometry>
      <mesh filename="package://ar1_description/meshes/caster_front_left_1.stl" scale="0.001 0.001 0.001"/>
    </geometry>
    <material name="silver"/>
  </visual>
  <collision>
    <origin xyz="-0.287845 -0.205 -0.0" rpy="0 0 0"/>
    <geometry>
      <mesh filename="package://ar1_description/meshes/caster_front_left_1.stl" scale="0.001 0.001 0.001"/>
    </geometry>
  </collision>
</link>

<link name="caster_back_left_1">
  <inertial>
    <origin xyz="0.02108260824199909 -0.049962879339778055 -0.05955238023566574" rpy="0 0 0"/>
    <mass value="0.7818323769298068"/>
    <inertia ixx="0.000725" iyy="0.001027" izz="0.000456" ixy="-0.0" iyz="0.0" ixz="0.000214"/>
  </inertial>
  <visual>
    <origin xyz="0.287845 -0.205 -0.0" rpy="0 0 0"/>
    <geometry>
      <mesh filename="package://ar1_description/meshes/caster_back_left_1.stl" scale="0.001 0.001 0.001"/>
    </geometry>
    <material name="silver"/>
  </visual>
  <collision>
    <origin xyz="0.287845 -0.205 -0.0" rpy="0 0 0"/>
    <geometry>
      <mesh filename="package://ar1_description/meshes/caster_back_left_1.stl" scale="0.001 0.001 0.001"/>
    </geometry>
  </collision>
</link>

<link name="caster_front_right_1">
  <inertial>
    <origin xyz="0.02108183322783813 0.050037120660218815 -0.05955238023566576" rpy="0 0 0"/>
    <mass value="0.7818323769298068"/>
    <inertia ixx="0.000725" iyy="0.001027" izz="0.000456" ixy="-0.0" iyz="0.0" ixz="0.000214"/>
  </inertial>
  <visual>
    <origin xyz="-0.287845 0.205 -0.0" rpy="0 0 0"/>
    <geometry>
      <mesh filename="package://ar1_description/meshes/caster_front_right_1.stl" scale="0.001 0.001 0.001"/>
    </geometry>
    <material name="silver"/>
  </visual>
  <collision>
    <origin xyz="-0.287845 0.205 -0.0" rpy="0 0 0"/>
    <geometry>
      <mesh filename="package://ar1_description/meshes/caster_front_right_1.stl" scale="0.001 0.001 0.001"/>
    </geometry>
  </collision>
</link>

<link name="caster_back_right_1">
  <inertial>
    <origin xyz="0.02108260824199909 0.05003712066021826 -0.05955238023566574" rpy="0 0 0"/>
    <mass value="0.7818323769298068"/>
    <inertia ixx="0.000725" iyy="0.001027" izz="0.000456" ixy="-0.0" iyz="0.0" ixz="0.000214"/>
  </inertial>
  <visual>
    <origin xyz="0.287845 0.205 -0.0" rpy="0 0 0"/>
    <geometry>
      <mesh filename="package://ar1_description/meshes/caster_back_right_1.stl" scale="0.001 0.001 0.001"/>
    </geometry>
    <material name="silver"/>
  </visual>
  <collision>
    <origin xyz="0.287845 0.205 -0.0" rpy="0 0 0"/>
    <geometry>
      <mesh filename="package://ar1_description/meshes/caster_back_right_1.stl" scale="0.001 0.001 0.001"/>
    </geometry>
  </collision>
</link>

<link name="outer_body_1_1">
  <inertial>
    <origin xyz="-0.002130729408293789 -2.1384314998579254e-15 0.05240276292973794" rpy="0 0 0"/>
    <mass value="35.15665247678721"/>
    <inertia ixx="1.415267" iyy="2.662894" izz="3.798123" ixy="-0.0" iyz="-0.0" ixz="0.003753"/>
  </inertial>
  <visual>
    <origin xyz="-0.0 -0.0 -0.005" rpy="0 0 0"/>
    <geometry>
      <mesh filename="package://ar1_description/meshes/outer_body_1_1.stl" scale="0.001 0.001 0.001"/>
    </geometry>
    <material name="silver"/>
  </visual>
  <collision>
    <origin xyz="-0.0 -0.0 -0.005" rpy="0 0 0"/>
    <geometry>
      <mesh filename="package://ar1_description/meshes/outer_body_1_1.stl" scale="0.001 0.001 0.001"/>
    </geometry>
  </collision>
</link>

<link name="outer_body_2_1">
  <inertial>
    <origin xyz="-0.005947186083510445 -0.0003326593358035886 0.0002500000000000002" rpy="0 0 0"/>
    <mass value="1.2030304448634093"/>
    <inertia ixx="0.021334" iyy="0.052144" izz="0.073477" ixy="7e-06" iyz="-0.0" ixz="0.0"/>
  </inertial>
  <visual>
    <origin xyz="-0.0 -0.0 -0.11" rpy="0 0 0"/>
    <geometry>
      <mesh filename="package://ar1_description/meshes/outer_body_2_1.stl" scale="0.001 0.001 0.001"/>
    </geometry>
    <material name="silver"/>
  </visual>
  <collision>
    <origin xyz="-0.0 -0.0 -0.11" rpy="0 0 0"/>
    <geometry>
      <mesh filename="package://ar1_description/meshes/outer_body_2_1.stl" scale="0.001 0.001 0.001"/>
    </geometry>
  </collision>
</link>

<link name="lidar_1">
  <inertial>
    <origin xyz="-1.1102230246251565e-16 1.0573075148748461e-16 0.08999999999999996" rpy="0 0 0"/>
    <mass value="3.156672298327024"/>
    <inertia ixx="0.002946" iyy="0.002946" izz="0.002525" ixy="-0.0" iyz="-0.0" ixz="-0.0"/>
  </inertial>
  <visual>
    <origin xyz="-0.3 -0.0 -0.005" rpy="0 0 0"/>
    <geometry>
      <mesh filename="package://ar1_description/meshes/lidar_1.stl" scale="0.001 0.001 0.001"/>
    </geometry>
    <material name="silver"/>
  </visual>
  <collision>
    <origin xyz="-0.3 -0.0 -0.005" rpy="0 0 0"/>
    <geometry>
      <mesh filename="package://ar1_description/meshes/lidar_1.stl" scale="0.001 0.001 0.001"/>
    </geometry>
  </collision>
</link>

<link name="wheel_left_1">
  <inertial>
    <origin xyz="-0.09924300000000004 -0.23749999999999993 -0.050000000000000364" rpy="0 0 0"/>
    <mass value="8.296271803811733"/>
    <inertia ixx="0.016903" iyy="0.031011" izz="0.016903" ixy="-0.0" iyz="-0.0" ixz="0.0"/>
  </inertial>
  <visual>
    <origin xyz="-0.099243 -0.455 -0.025" rpy="0 0 0"/>
    <geometry>
      <mesh filename="package://ar1_description/meshes/wheel_left_1.stl" scale="0.001 0.001 0.001"/>
    </geometry>
    <material name="silver"/>
  </visual>
  <collision>
    <origin xyz="-0.099243 -0.455 -0.025" rpy="0 0 0"/>
    <geometry>
      <mesh filename="package://ar1_description/meshes/wheel_left_1.stl" scale="0.001 0.001 0.001"/>
    </geometry>
  </collision>
</link>

<link name="wheel_right_1">
  <inertial>
    <origin xyz="-0.09924299999999993 -0.0724999999999999 -0.05000000000000013" rpy="0 0 0"/>
    <mass value="8.296271803811733"/>
    <inertia ixx="0.016903" iyy="0.031011" izz="0.016903" ixy="-0.0" iyz="-0.0" ixz="-0.0"/>
  </inertial>
  <visual>
    <origin xyz="-0.099243 0.145 -0.025" rpy="0 0 0"/>
    <geometry>
      <mesh filename="package://ar1_description/meshes/wheel_right_1.stl" scale="0.001 0.001 0.001"/>
    </geometry>
    <material name="silver"/>
  </visual>
  <collision>
    <origin xyz="-0.099243 0.145 -0.025" rpy="0 0 0"/>
    <geometry>
      <mesh filename="package://ar1_description/meshes/wheel_right_1.stl" scale="0.001 0.001 0.001"/>
    </geometry>
  </collision>
</link>

<joint name="bracket_left" type="fixed">
  <origin xyz="0.013 0.125 0.0" rpy="0 0 0"/>
  <parent link="base_link"/>
  <child link="drive_wheel_bracket_left_1"/>
</joint>

<joint name="bracket_right" type="fixed">
  <origin xyz="0.013 -0.125 0.0" rpy="0 0 0"/>
  <parent link="base_link"/>
  <child link="drive_wheel_bracket_right_1"/>
</joint>

<joint name="caster_front_left" type="fixed">
  <origin xyz="0.287845 0.205 0.0" rpy="0 0 0"/>
  <parent link="base_link"/>
  <child link="caster_front_left_1"/>
</joint>

<joint name="caster_back_left" type="fixed">
  <origin xyz="-0.287845 0.205 0.0" rpy="0 0 0"/>
  <parent link="base_link"/>
  <child link="caster_back_left_1"/>
</joint>

<joint name="caster_front_right" type="fixed">
  <origin xyz="0.287845 -0.205 0.0" rpy="0 0 0"/>
  <parent link="base_link"/>
  <child link="caster_front_right_1"/>

</joint>

<joint name="caster_back_right" type="fixed">
  <origin xyz="-0.287845 -0.205 0.0" rpy="0 0 0"/>
  <parent link="base_link"/>
  <child link="caster_back_right_1"/>

</joint>

<joint name="outer_body_1" type="fixed">
  <origin xyz="0.0 0.0 0.005" rpy="0 0 0"/>
  <parent link="base_link"/>
  <child link="outer_body_1_1"/>
</joint>

<joint name="outer_body_2" type="fixed">
  <origin xyz="0.0 0.0 0.105" rpy="0 0 0"/>
  <parent link="outer_body_1_1"/>
  <child link="outer_body_2_1"/>
</joint>

<joint name="lidar_joint" type="fixed">
  <origin xyz="0.3 0.0 0.005" rpy="0 0 0"/>
  <parent link="base_link"/>
  <child link="lidar_1"/>
</joint>

<joint name="wheel_left" type="continuous">
  <origin xyz="0.086243 0.33 0.025" rpy="0 0 0"/>
  <parent link="drive_wheel_bracket_left_1"/>
  <child link="wheel_left_1"/>
  <axis xyz="0 1 0"/>

</joint>

<joint name="wheel_right" type="continuous">
  <origin xyz="0.086243 -0.02 0.025" rpy="0 0 0"/>
  <parent link="drive_wheel_bracket_right_1"/>
  <child link="wheel_right_1"/>
  <axis xyz="0 1 0"/>

</joint>

</robot>
